Workbook
Name AcquisitionFee: 'Provided - CAP Acct. 1'!$H$114
Name AssetManagementFee: 'Provided - CAP Acct. 1'!$H$115
Name ClosingDate: 'Provided - CAP Acct. 1'!$H$18
Name CoInvestorEquityContributionPct: 'Provided - CAP Acct. 1'!$M$13
Name CommonEquityOBalance: 'Provided - CAP Acct. 1'!$L$11
Name CommonEquityWeight: 'Q1 - CAP Acct. 2'!$I$23
Name ConstLoanExtensionDate: 'Provided - CAP Acct. 1'!$R$17
Name ConstLoanExtensionDummy: 'Provided - CAP Acct. 1'!$R$16
Name ConstLoanExtensionFee: 'Provided - CAP Acct. 1'!$R$15
Name ConstLoanMaturity: 'Provided - CAP Acct. 1'!$Q$13
Name ConstLoanMaturityDate: 'Provided - CAP Acct. 1'!$R$13
Name ConstLoanOBalance: 'Provided - CAP Acct. 1'!$R$9
Name ConstLoanOFees: 'Provided - CAP Acct. 1'!$H$14
Name ConstLoanOriginationDate: 'Provided - CAP Acct. 1'!$R$12
Name ConstLoanSpread: 'Provided - CAP Acct. 1'!$R$11
Name ConstLoanType: 'Provided - CAP Acct. 1'!$R$14
Name Contingency: 'Provided - CAP Acct. 1'!$H$12
Name CumulEquityInvested: 'Provided - CAP Acct. 1'!A$56
Name DaysInMonth: 'Provided - CAP Acct. 1'!A$29
Name DaysOpen: Inputs!$F$8
Name DiscountRateHotel: Inputs!$C$13
Name DispositionFee: 'Provided - CAP Acct. 1'!$H$116
Name ExitDate: 'Provided - CAP Acct. 1'!$H$20
Name GraphVariable: Inputs!$B$35
Name GrossSaleProceedsHotel: Valuation!$G$20
Name GroupADR: Inputs!$F$14
Name GroupFBWeight: Inputs!$F$17
Name HardCost: 'Provided - CAP Acct. 1'!$H$11
Name HistOccupancy: Inputs!$F$9
Name HoldingDates: 'Provided - CAP Acct. 1'!$I$28:$CO$28
Name HoldingPeriod: Inputs!$C$12
Name HotelForecastTable: Inputs!$B$23:$H$32
Name InterestReserve: 'Provided - CAP Acct. 1'!$H$13
Name LandCost: 'Provided - CAP Acct. 1'!$H$9
Name MiscRate: Inputs!$F$18
Name NOI_Today: 'Provided - CAP Acct. 1'!A$38
Name NumberRooms: Inputs!$F$7
Name OccGroupWeight: Inputs!$F$11
Name OccTransientWeight: Inputs!$F$10
Name OpeningDate: 'Provided - CAP Acct. 1'!$H$19
Name PermanentLoanAmortization: 'Provided - CAP Acct. 1'!$V$14
Name PermanentLoanDebtServiceDummy: 'Provided - CAP Acct. 1'!A$108
Name PermanentLoanDSCR: 'Provided - CAP Acct. 1'!$V$11
Name PermanentLoanMaturityDate: 'Provided - CAP Acct. 1'!$V$17
Name PermanentLoanMortgageConstant: 'Provided - CAP Acct. 1'!$V$15
Name PermanentLoanNOI: 'Provided - CAP Acct. 1'!$V$10
Name PermanentLoanOBalance: 'Provided - CAP Acct. 1'!$V$9
Name PermanentLoanOriginationDate: 'Provided - CAP Acct. 1'!$V$16
Name PermanentLoanPoints: 'Provided - CAP Acct. 1'!$V$12
Name PermanentLoanPPMTDummy: 'Provided - CAP Acct. 1'!$V$19
Name PermanentLoanPPMTFee: 'Provided - CAP Acct. 1'!$V$18
Name PermanentLoanRate: 'Provided - CAP Acct. 1'!$V$13
Name PreferredEquityOBalance: 'Provided - CAP Acct. 1'!$R$19
Name PreferredEquityReturn_Case1: 'Provided - CAP Acct. 1'!$R$20
Name PreferredEquityReturn_Case2: 'Q1 - CAP Acct. 2'!$R$20
Name PreferredEquityWeight: 'Q1 - CAP Acct. 2'!$I$24
Name Probabilities: Scenario!$P$19:$P$21
Name ScenarioTable: Scenario!$B$19:$O$23
Name SellingCost: Inputs!$C$15
Name SoftCost: 'Provided - CAP Acct. 1'!$H$10

Sheet Instructions
B2: Exam 1
B3: Comparing Complex Deal Structures
B5: Instructions

Sheet Inputs
B2: =Instructions!B3 -> Comparing Complex Deal Structures
B4: Inputs - Income
B6: Building Name | C6: Hotel "Excel'sior" | D6: Hotel Assumptions
B7: Address | C7: Geeky Valley | D7: Number of Rooms | F7: 250
B8: City | C8: Brainville | D8: Days Open | F8: 365
B9: State | C9: CPU | D9: Historical Occupancy | F9: =C23 -> 0.7
D10: Transient | F10: 0.6
B11: Analysis Begin Date | C11: 44197 | D11: Group | F11: 0.4
B12: Holding Period | C12: 5 | D12: Average Rate (ADR) | F12: =SUMPRODUCT(F10:F11,F13:F14) -> 167
B13: Discount Rate - Hotel | C13: 0.1 | D13: Transient | F13: =C27 -> 185
B14: Terminal Cap Rate - Hotel | C14: =Scenario!Q9 -> 0.085 | D14: Group | F14: =C28 -> 140
B15: Selling Cost | C15: 0.03 | D15: F&B % of Room Rev | F15: =SUMPRODUCT(F10:F11,F16:F17) -> 0.36
D16: Transient | F16: 0.2
D17: Group | F17: 0.6
D18: Miscellaneous | F18: 0.04
B21: Hotel Forecast
C22: =YEAR(C11) -> 2021 | D22: =C22+1 -> 2022 | E22: =D22+1 -> 2023 | F22: =E22+1 -> 2024 | G22: =F22+1 -> 2025 | H22: =G22+1 -> 2026
B23: Occupancy | C23: =Scenario!E9 -> 0.7 | D23: =Scenario!F9 -> 0.75 | E23: =Scenario!G9 -> 0.79 | F23: =Scenario!H9 -> 0.81 | G23: =Scenario!I9 -> 0.79 | H23: =Scenario!J9 -> 0.8
B24: Transient Occupancy Weight | C24: 0.6 | D24: 0.65 | E24: 0.55 | F24: 0.4 | G24: 0.55 | H24: 0.7
B25: Group Occupancy Weight | C25: 0.4 | D25: 0.35 | E25: 0.45 | F25: 0.6 | G25: 0.45 | H25: 0.3
B26: ADR Overall | C26: 164 | D26: 167.25 | E26: 168.65 | F26: 170 | G26: 174.25 | H26: 183
B27: Transient ADR | C27: =Scenario!K9 -> 185 | D27: =Scenario!L9 -> 190 | E27: =Scenario!M9 -> 188 | F27: =Scenario!N9 -> 185 | G27: =Scenario!O9 -> 191 | H27: =Scenario!P9 -> 192
B28: Group ADR | C28: 140 | D28: 138 | E28: 145 | F28: 160 | G28: 155 | H28: 155
B29: FB % of Room Rev | C29: 0.36 | D29: 0.34 | E29: 0.38 | F29: 0.44 | G29: 0.38 | H29: 0.32
B30: Transient FB % of Room Rev | C30: 0.2 | D30: 0.2 | E30: 0.2 | F30: 0.2 | G30: 0.2 | H30: 0.2
B31: Group FB % of Room Rev | C31: 0.6 | D31: 0.6 | E31: 0.6 | F31: 0.6 | G31: 0.6 | H31: 0.6
B32: Inflation | C32: 0.02 | D32: 0.02 | E32: 0.02 | F32: 0.02 | G32: 0.02 | H32: 0.02
B34: Graph - Hotel | C34: =YEAR(C11) -> 2021 | D34: =C34+1 -> 2022 | E34: =D34+1 -> 2023 | F34: =E34+1 -> 2024 | G34: =F34+1 -> 2025 | H34: =G34+1 -> 2026
B35: Occupancy | C35: =VLOOKUP(GraphVariable,HotelForecastTable,MATCH(C22,$B$22:$H$22,0),0) -> 0.7 | D35: =VLOOKUP(GraphVariable,HotelForecastTable,MATCH(D22,$B$22:$H$22,0),0) -> 0.75 | E35: =VLOOKUP(GraphVariable,HotelForecastTable,MATCH(E22,$B$22:$H$22,0),0) -> 0.79 | F35: =VLOOKUP(GraphVariable,HotelForecastTable,MATCH(F22,$B$22:$H$22,0),0) -> 0.81 | G35: =VLOOKUP(GraphVariable,HotelForecastTable,MATCH(G22,$B$22:$H$22,0),0) -> 0.79 | H35: =VLOOKUP(GraphVariable,HotelForecastTable,MATCH(H22,$B$22:$H$22,0),0) -> 0.8
B36: REVPAR | C36: =C23*C26 -> 114.8 | D36: =D23*D26 -> 125.4375 | E36: =E23*E26 -> 133.2335 | F36: =F23*F26 -> 137.7 | G36: =G23*G26 -> 137.6575 | H36: =H23*H26 -> 146.4
B37: ="Hotel - "&GraphVariable -> Hotel - Occupancy
B55: Inputs - Operating Expenses
B57: Hotel Operating Expenses
C59: Historical | E59: Mix | H59: Credit
B60: DISTRIBUTED | C60: Dollar Amount | D60: % Rev | E60: PAR | F60: POR | G60: % of Rev | H60: PAR | I60: POR | J60: % Rev
B61: Rooms | C61: =NOI!C12*D61 -> 3200137.5 | D61: 0.3 | E61: 0.2 | F61: 0.2 | G61: 0.6 | H61: =$C61*E61/(NumberRooms*DaysOpen) -> 7.014 | I61: =C61*F61/(DaysOpen*NumberRooms*HistOccupancy) -> 10.02 | J61: =D61*G61 -> 0.18
B62: Total F&B | C62: =NOI!C26*D62 -> 2851380 | D62: 0.8 | E62: 0.2 | F62: 0 | G62: 0.8 | H62: =$C62*E62/(NumberRooms*DaysOpen) -> 6.2496 | I62: =C62*F62/(DaysOpen*NumberRooms*HistOccupancy) -> 0 | J62: =D62*G62 -> 0.64
B63: Miscellaneous | C63: =NOI!C29*D63 -> 298679.5 | D63: 0.7 | E63: 0.2 | F63: 0 | G63: 0.8 | H63: =$C63*E63/(NumberRooms*DaysOpen) -> 0.65464 | I63: =C63*F63/(DaysOpen*NumberRooms*HistOccupancy) -> 0 | J63: =D63*G63 -> 0.56
B64: * There are no distributed expenses for the commercial space
C66: Historical | E66: Mix | H66: Credit
...

Sheet Construction
B2: =Inputs!B2 -> Comparing Complex Deal Structures
B4: Input: Construction Schedule
B6: $ Amount | E6: Months | Q6: Months
D7: Total | E7: =Inputs!C11-1 -> 44196 | F7: =EOMONTH(E7,1) -> 44227 | G7: =EOMONTH(F7,1) -> 44255 | H7: =EOMONTH(G7,1) -> 44286 | I7: =EOMONTH(H7,1) -> 44316 | J7: =EOMONTH(I7,1) -> 44347 | K7: =EOMONTH(J7,1) -> 44377 | L7: =EOMONTH(K7,1) -> 44408 | M7: =EOMONTH(L7,1) -> 44439 | ... AC7: =EOMONTH(AB7,1) -> 44926
B9: Land / Acquisition | D9: ='Provided - CAP Acct. 1'!H9 -> 5000000 | E9: =$D9*E37 -> 5000000 | F9: =$D9*F37 -> 0 | G9: =$D9*G37 -> 0 | H9: =$D9*H37 -> 0 | I9: =$D9*I37 -> 0 | J9: =$D9*J37 -> 0 | K9: =$D9*K37 -> 0 | L9: =$D9*L37 -> 0 | ... AC9: =$D9*AC37 -> 0 | AD9: x
B10: Finance & Legal | D10: 300000 | E10: =$D10*E38 -> 300000 | F10: =$D10*F38 -> 0 | G10: =$D10*G38 -> 0 | H10: =$D10*H38 -> 0 | I10: =$D10*I38 -> 0 | J10: =$D10*J38 -> 0 | K10: =$D10*K38 -> 0 | L10: =$D10*L38 -> 0 | ... AC10: =$D10*AC38 -> 0 | AD10: x
B11: Development | D11: 500000 | E11: =$D11*E39 -> 71428.571 | F11: =$D11*F39 -> 17857.143 | G11: =$D11*G39 -> 17857.143 | H11: =$D11*H39 -> 17857.143 | I11: =$D11*I39 -> 17857.143 | J11: =$D11*J39 -> 17857.143 | K11: =$D11*K39 -> 17857.143 | L11: =$D11*L39 -> 17857.143 | ... AC11: =$D11*AC39 -> 17857.143 | AD11: x
B12: Design & Engineering | D12: 1700000 | E12: =$D12*E40 -> 1020000 | F12: =$D12*F40 -> 136000 | G12: =$D12*G40 -> 136000 | H12: =$D12*H40 -> 136000 | I12: =$D12*I40 -> 136000 | J12: =$D12*J40 -> 136000 | K12: =$D12*K40 -> 0 | L12: =$D12*L40 -> 0 | ... AC12: =$D12*AC40 -> 0 | AD12: x
B13: Permits & Fees | D13: 1300000 | E13: =$D13*E41 -> 1300000 | F13: =$D13*F41 -> 0 | G13: =$D13*G41 -> 0 | H13: =$D13*H41 -> 0 | I13: =$D13*I41 -> 0 | J13: =$D13*J41 -> 0 | K13: =$D13*K41 -> 0 | L13: =$D13*L41 -> 0 | ... AC13: =$D13*AC41 -> 0 | AD13: x
B14: FF&E (Hard Costs) | D14: 1800000 | E14: =$D14*E42 -> 0 | F14: =$D14*F42 -> 0 | G14: =$D14*G42 -> 0 | H14: =$D14*H42 -> 0 | I14: =$D14*I42 -> 0 | J14: =$D14*J42 -> 0 | K14: =$D14*K42 -> 0 | L14: =$D14*L42 -> 0 | ... AC14: =$D14*AC42 -> 0 | AD14: x
B15: Hard Costs | D15: =SUM(D16:D24) -> 15070000 | E15: =SUM(E16:E24) -> 183700 | F15: =SUM(F16:F24) -> 139700 | G15: =SUM(G16:G24) -> 139700 | H15: =SUM(H16:H24) -> 161700 | I15: =SUM(I16:I24) -> 145200 | J15: =SUM(J16:J24) -> 99000 | K15: =SUM(K16:K24) -> 411631.58 | ... AC15: =SUM(AC16:AC24) -> 992431.58 | AD15: x
B16: Pre-Construction Services | D16: 100000 | E16: =$D16*E44 -> 50000 | F16: =$D16*F44 -> 10000 | G16: =$D16*G44 -> 10000 | H16: =$D16*H44 -> 10000 | I16: =$D16*I44 -> 20000 | J16: =$D16*J44 -> 0 | K16: =$D16*K44 -> 0 | L16: =$D16*L44 -> 0 | ... AC16: =$D16*AC44 -> 0 | AD16: x
B17: Demolition/Remediation | D17: 400000 | E17: =$D17*E45 -> 72000 | F17: =$D17*F45 -> 72000 | G17: =$D17*G45 -> 72000 | H17: =$D17*H45 -> 72000 | I17: =$D17*I45 -> 112000 | J17: =$D17*J45 -> 0 | K17: =$D17*K45 -> 0 | L17: =$D17*L45 -> 0 | ... AC17: =$D17*AC45 -> 0 | AD17: x
B18: Tower Super Structure | D18: 6000000 | E18: =$D18*E46 -> 0 | F18: =$D18*F46 -> 0 | G18: =$D18*G46 -> 0 | H18: =$D18*H46 -> 0 | I18: =$D18*I46 -> 0 | J18: =$D18*J46 -> 0 | K18: =$D18*K46 -> 284210.53 | L18: =$D18*L46 -> 284210.53 | ... AC18: =$D18*AC46 -> 884210.53 | AD18: x
B19: B-1 Lobby & Functions | D19: 3600000 | E19: =$D19*E47 -> 0 | F19: =$D19*F47 -> 0 | G19: =$D19*G47 -> 0 | H19: =$D19*H47 -> 0 | I19: =$D19*I47 -> 0 | J19: =$D19*J47 -> 0 | K19: =$D19*K47 -> 0 | L19: =$D19*L47 -> 0 | ... AC19: =$D19*AC47 -> 0 | AD19: x
B20: Parking Garage | D20: 2300000 | E20: =$D20*E48 -> 0 | F20: =$D20*F48 -> 0 | G20: =$D20*G48 -> 0 | H20: =$D20*H48 -> 0 | I20: =$D20*I48 -> 0 | J20: =$D20*J48 -> 0 | K20: =$D20*K48 -> 0 | L20: =$D20*L48 -> 207000 | ... AC20: =$D20*AC48 -> 0 | AD20: x
B21: Site Utilities | D21: 1000000 | E21: =$D21*E49 -> 0 | F21: =$D21*F49 -> 0 | G21: =$D21*G49 -> 0 | H21: =$D21*H49 -> 0 | I21: =$D21*I49 -> 0 | J21: =$D21*J49 -> 90000 | K21: =$D21*K49 -> 90000 | L21: =$D21*L49 -> 90000 | ... AC21: =$D21*AC49 -> 0 | AD21: x
B22: Off Site / Street Improvements | D22: 100000 | E22: =$D22*E50 -> 0 | F22: =$D22*F50 -> 0 | G22: =$D22*G50 -> 0 | H22: =$D22*H50 -> 0 | I22: =$D22*I50 -> 0 | J22: =$D22*J50 -> 0 | K22: =$D22*K50 -> 0 | L22: =$D22*L50 -> 0 | ... AC22: =$D22*AC50 -> 18000 | AD22: x
B23: Adjacent Property Mitigation Measures | D23: 200000 | E23: =$D23*E51 -> 45000 | F23: =$D23*F51 -> 45000 | G23: =$D23*G51 -> 45000 | H23: =$D23*H51 -> 65000 | I23: =$D23*I51 -> 0 | J23: =$D23*J51 -> 0 | K23: =$D23*K51 -> 0 | L23: =$D23*L51 -> 0 | ... AC23: =$D23*AC51 -> 0 | AD23: x
B24: General Conditions and Fees | C24: 0.1 | D24: =SUM(D16:D23)*C24 -> 1370000 | E24: =SUM(E16:E23)*$C24 -> 16700 | F24: =SUM(F16:F23)*$C24 -> 12700 | G24: =SUM(G16:G23)*$C24 -> 12700 | H24: =SUM(H16:H23)*$C24 -> 14700 | I24: =SUM(I16:I23)*$C24 -> 13200 | J24: =SUM(J16:J23)*$C24 -> 9000 | K24: =SUM(K16:K23)*$C24 -> 37421.053 | L24: =SUM(L16:L23)*$C24 -> 58121.053 | ... AC24: =SUM(AC16:AC23)*$C24 -> 90221.053 | AD24: x
B25: OS&E - Technology | D25: 700000 | E25: =$D25*E53 -> 0 | F25: =$D25*F53 -> 0 | G25: =$D25*G53 -> 0 | H25: =$D25*H53 -> 0 | I25: =$D25*I53 -> 0 | J25: =$D25*J53 -> 0 | K25: =$D25*K53 -> 0 | L25: =$D25*L53 -> 0 | ... AC25: =$D25*AC53 -> 0 | AD25: x
B26: Pre-Opening - Working Capital | D26: 800000 | E26: =$D26*E54 -> 0 | F26: =$D26*F54 -> 0 | G26: =$D26*G54 -> 0 | H26: =$D26*H54 -> 0 | I26: =$D26*I54 -> 0 | J26: =$D26*J54 -> 0 | K26: =$D26*K54 -> 0 | L26: =$D26*L54 -> 0 | ... AC26: =$D26*AC54 -> 200000 | AD26: x
B27: Subtotal | D27: =SUM(D9:D15,D25:D26) -> 27170000 | E27: =SUM(E9:E15,E25:E26) -> 7875128.6 | F27: =SUM(F9:F15,F25:F26) -> 293557.14 | G27: =SUM(G9:G15,G25:G26) -> 293557.14 | H27: =SUM(H9:H15,H25:H26) -> 315557.14 | I27: =SUM(I9:I15,I25:I26) -> 299057.14 | J27: =SUM(J9:J15,J25:J26) -> 252857.14 | K27: =SUM(K9:K15,K25:K26) -> 429488.72 | ... AC27: =SUM(AC9:AC15,AC25:AC26) -> 1210288.7 | AD27: x
B29: Escalation | C29: 0.03 | D29: =C29*(D27-D9) -> 665100 | E29: =$C29*SUM(E10:E15,E25:E26) -> 86253.857 | F29: =$C29*SUM(F10:F15,F25:F26) -> 8806.7143 | G29: =$C29*SUM(G10:G15,G25:G26) -> 8806.7143 | H29: =$C29*SUM(H10:H15,H25:H26) -> 9466.7143 | I29: =$C29*SUM(I10:I15,I25:I26) -> 8971.7143 | J29: =$C29*SUM(J10:J15,J25:J26) -> 7585.7143 | K29: =$C29*SUM(K10:K15,K25:K26) -> 12884.662 | L29: =$C29*SUM(L10:L15,L25:L26) -> 19715.662 | ... AC29: =$C29*SUM(AC10:AC15,AC25:AC26) -> 36308.662 | AD29: x
B30: Project Contingency | C30: 0.03 | D30: =C30*(D27+D29-D9) -> 685053 | E30: =$C30*SUM(E10:E15,E25:E26,E29) -> 88841.473 | F30: =$C30*SUM(F10:F15,F25:F26,F29) -> 9070.9157 | G30: =$C30*SUM(G10:G15,G25:G26,G29) -> 9070.9157 | H30: =$C30*SUM(H10:H15,H25:H26,H29) -> 9750.7157 | I30: =$C30*SUM(I10:I15,I25:I26,I29) -> 9240.8657 | J30: =$C30*SUM(J10:J15,J25:J26,J29) -> 7813.2857 | K30: =$C30*SUM(K10:K15,K25:K26,K29) -> 13271.202 | L30: =$C30*SUM(L10:L15,L25:L26,L29) -> 20307.132 | ... AC30: =$C30*SUM(AC10:AC15,AC25:AC26,AC29) -> 37397.922 | AD30: x
B32: Total Costs | D32: =SUM(D27,D29:D30) -> 28520153 | E32: =SUM(E27,E29:E30) -> 8050223.9 | F32: =SUM(F27,F29:F30) -> 311434.77 | G32: =SUM(G27,G29:G30) -> 311434.77 | H32: =SUM(H27,H29:H30) -> 334774.57 | I32: =SUM(I27,I29:I30) -> 317269.72 | J32: =SUM(J27,J29:J30) -> 268256.14 | K32: =SUM(K27,K29:K30) -> 455644.58 | ... AC32: =SUM(AC27,AC29:AC30) -> 1283995.3
B34: % Allocation
E35: =E6 -> Months | Q35: =Q6 -> Months
D36: Total | E36: =E7 -> 44196 | F36: =F7 -> 44227 | G36: =G7 -> 44255 | H36: =H7 -> 44286 | I36: =I7 -> 44316 | J36: =J7 -> 44347 | K36: =K7 -> 44377 | L36: =L7 -> 44408 | ... AC36: =AC7 -> 44926 | AD36: x
B37: Land / Acquisition | D37: =SUM(E37:AC37) -> 1 | E37: 1 | AD37: x
B38: Finance & Legal | D38: =SUM(E38:AC38) -> 1 | E38: 1 | AD38: x
B39: Development | D39: =SUM(E39:AC39) -> 1 | E39: 0.14285714 | F39: =1/28 -> 0.035714286 | G39: =1/28 -> 0.035714286 | H39: =1/28 -> 0.035714286 | I39: =1/28 -> 0.035714286 | J39: =1/28 -> 0.035714286 | K39: =1/28 -> 0.035714286 | L39: =1/28 -> 0.035714286 | M39: =1/28 -> 0.035714286 | ... AC39: =1/28 -> 0.035714286 | AD39: x
B40: Design & Engineering | D40: =SUM(E40:AC40) -> 1 | E40: 0.6 | F40: 0.08 | G40: 0.08 | H40: 0.08 | I40: 0.08 | J40: 0.08 | AD40: x
B41: Permits & Fees | D41: =SUM(E41:AC41) -> 1 | E41: 1 | AD41: x
B42: FF&E (Hard Costs) | D42: =SUM(E42:AC42) -> 1 | V42: 0.2 | W42: 0.2 | X42: 0.2 | Y42: 0.2 | Z42: 0.2 | AD42: x
B43: Hard Costs
B44: Pre-Construction Services | D44: =SUM(E44:AC44) -> 1 | E44: 0.5 | F44: 0.1 | G44: 0.1 | H44: 0.1 | I44: 0.2 | AD44: x
B45: Demolition/Remediation | D45: =SUM(E45:AC45) -> 1 | E45: =90%/5 -> 0.18 | F45: =90%/5 -> 0.18 | G45: =90%/5 -> 0.18 | H45: =90%/5 -> 0.18 | I45: 0.28 | AD45: x
B46: Tower Super Structure | D46: =SUM(E46:AC46) -> 1 | K46: =0.9/19 -> 0.047368421 | L46: =0.9/19 -> 0.047368421 | M46: =0.9/19 -> 0.047368421 | N46: =0.9/19 -> 0.047368421 | O46: =0.9/19 -> 0.047368421 | P46: =0.9/19 -> 0.047368421 | Q46: =0.9/19 -> 0.047368421 | R46: =0.9/19 -> 0.047368421 | ... AB46: =0.9/19 -> 0.047368421 | AC46: 0.14736842 | AD46: x
B47: B-1 Lobby & Functions | D47: =SUM(E47:AC47) -> 1 | R47: =0.9/10 -> 0.09 | S47: =0.9/10 -> 0.09 | T47: =0.9/10 -> 0.09 | U47: =0.9/10 -> 0.09 | V47: =0.9/10 -> 0.09 | W47: =0.9/10 -> 0.09 | X47: =0.9/10 -> 0.09 | Y47: =0.9/10 -> 0.09 | Z47: =0.9/10 -> 0.09 | AA47: 0.19 | AD47: x
...

Sheet Libor
B2: =Inputs!B2 -> Comparing Complex Deal Structures
B4: Input: Forward Curves
B7: Forward Curves
C9: =Construction!E36 -> 44196 | D9: =EOMONTH(C9,1) -> 44227 | E9: =EOMONTH(D9,1) -> 44255 | F9: =EOMONTH(E9,1) -> 44286 | G9: =EOMONTH(F9,1) -> 44316 | H9: =EOMONTH(G9,1) -> 44347 | I9: =EOMONTH(H9,1) -> 44377 | J9: =EOMONTH(I9,1) -> 44408 | K9: =EOMONTH(J9,1) -> 44439 | ... DS9: =EOMONTH(DR9,1) -> 47848
B11: 1 Month USD LIBOR Forward Curve | C11: 0.0014925 | D11: 0.0015746 | E11: 0.0016548 | F11: 0.0017305 | G11: 0.001734 | H11: 0.0016393 | I11: 0.0014936 | J11: 0.0013758 | K11: 0.0013131 | L11: 0.0013266 | M11: 0.0013896 | N11: 0.0014629 | O11: 0.0015439 | P11: 0.0016185 | Q11: 0.0016576 | R11: 0.0016731 | S11: 0.0016505 | T11: 0.001572 | U11: 0.0014832 | V11: 0.0014183 | W11: 0.0013636 | X11: 0.0013674 | Y11: 0.001432 | Z11: 0.0015107 | AA11: 0.0016359 | AB11: 0.0017925 | AC11: 0.0019195 | AD11: 0.002075 | AE11: 0.0022303 | AF11: 0.0023571 | AG11: 0.0024913 | AH11: 0.0026353 | AI11: 0.0027579 | AJ11: 0.0028946 | AK11: 0.003043 | AL11: 0.0031805 | AM11: 0.0033303 | AN11: 0.0034998 | AO11: 0.0036478 | AP11: 0.0038258 | AQ11: 0.004018 | AR11: 0.0041911 | AS11: 0.0043829 | AT11: 0.0045864 | AU11: 0.0047821 | AV11: 0.0049875 | AW11: 0.0052026 | AX11: 0.0054099 | AY11: 0.0056248 | AZ11: 0.0058518 | BA11: 0.0060465 | BB11: 0.0062646 | BC11: 0.006485 | BD11: 0.0066765 | BE11: 0.0068779 | BF11: 0.007081 | BG11: 0.0072712 | BH11: 0.0074647 | BI11: 0.0076678 | BJ11: 0.0078446 | BK11: 0.0080317 | BL11: 0.0082283 | BM11: 0.0083824 | BN11: 0.0085734 | BO11: 0.0087551 | BP11: 0.0089056 | BQ11: 0.009063 | BR11: 0.0092272 | BS11: 0.0093634 | BT11: 0.009509 | BU11: 0.0096645 | BV11: 0.0097949 | BW11: 0.0099351 | BX11: 0.010087 | BY11: 0.0102117 | BZ11: 0.0103548 | CA11: 0.0105052 | CB11: 0.0106149 | CC11: 0.0107642 | CD11: 0.0109069 | CE11: 0.0110244 | CF11: 0.0111505 | CG11: 0.0112862 | CH11: 0.0113958 | CI11: 0.0115155 | CJ11: 0.0116474 | CK11: 0.0117483 | CL11: 0.0118728 | CM11: 0.0120014 | CN11: 0.0120994 | CO11: 0.0122048 | CP11: 0.0123179 | CQ11: 0.0124019 | CR11: 0.0124959 | CS11: 0.0125986 | CT11: 0.0126789 | CU11: 0.0127668 | CV11: 0.0128674 | CW11: 0.0129406 | CX11: 0.0130316 | CY11: 0.0131334 | CZ11: 0.0132106 | DA11: 0.0133028 | DB11: 0.0134077 | DC11: 0.0134955 | DD11: 0.0135942 | DE11: 0.0137042 | DF11: 0.0137959 | DG11: 0.0138951 | DH11: 0.0140044 | DI11: 0.0140822 | DJ11: 0.0141723 | DK11: 0.0142638 | DL11: 0.0143205 | DM11: 0.0143813 | DN11: 0.014445 | DO11: 0.0144799 | DP11: 0.0145181 | DQ11: 0.0145623 | DR11: 0.0145799 | DS11: 0.0146052
B12: 3 Month USD LIBOR Forward Curve | C12: 0.0021475 | D12: 0.0021992 | E12: 0.0022525 | F12: 0.0023009 | G12: 0.002192 | H12: 0.0020936 | I12: 0.0019847 | J12: 0.0019824 | K12: 0.0019799 | L12: 0.0019778 | M12: 0.0020345 | N12: 0.0020929 | O12: 0.0021459 | P12: 0.0022904 | Q12: 0.0024348 | R12: 0.0025746 | S12: 0.0026436 | T12: 0.0027021 | U12: 0.0027627 | V12: 0.0028301 | W12: 0.002902 | X12: 0.0029671 | Y12: 0.0030416 | Z12: 0.003116 | AA12: 0.0031881 | AB12: 0.003294 | AC12: 0.0033838 | AD12: 0.0034832 | AE12: 0.0036139 | AF12: 0.0037283 | AG12: 0.0038508 | AH12: 0.0039962 | AI12: 0.0041464 | AJ12: 0.0042917 | AK12: 0.0044764 | AL12: 0.0046387 | AM12: 0.0048066 | AN12: 0.0049971 | AO12: 0.0051697 | AP12: 0.0053542 | AQ12: 0.0055518 | AR12: 0.0057366 | AS12: 0.0059342 | AT12: 0.0061428 | AU12: 0.0063447 | AV12: 0.0065465 | AW12: 0.0067595 | AX12: 0.0069724 | AY12: 0.0071923 | AZ12: 0.0073906 | BA12: 0.0075958 | BB12: 0.0078146 | BC12: 0.0080121 | BD12: 0.0081965 | BE12: 0.0084137 | BF12: 0.0085909 | BG12: 0.0087871 | BH12: 0.0089896 | BI12: 0.0091657 | BJ12: 0.0093539 | BK12: 0.0095422 | BL12: 0.0097121 | BM12: 0.0098821 | BN12: 0.0100577 | BO12: 0.0102206 | BP12: 0.0103679 | BQ12: 0.0105361 | BR12: 0.0106768 | BS12: 0.0108271 | BT12: 0.0109775 | BU12: 0.0111109 | BV12: 0.0112576 | BW12: 0.0113821 | BX12: 0.0115186 | BY12: 0.0116596 | BZ12: 0.0117874 | CA12: 0.0119273 | CB12: 0.0120536 | CC12: 0.0121935 | CD12: 0.0123276 | CE12: 0.0124752 | CF12: 0.0126003 | CG12: 0.0127377 | CH12: 0.0128795 | CI12: 0.013008 | CJ12: 0.0131311 | CK12: 0.0132542 | CL12: 0.0133733 | CM12: 0.0134906 | CN12: 0.0135901 | CO12: 0.0136967 | CP12: 0.0137896 | CQ12: 0.0138856 | CR12: 0.0139785 | CS12: 0.0140645 | CT12: 0.01414 | CU12: 0.0142182 | CV12: 0.0143079 | CW12: 0.0143892 | CX12: 0.0144761 | CY12: 0.0145711 | CZ12: 0.0146569 | DA12: 0.0147518 | DB12: 0.0148551 | DC12: 0.0149487 | DD12: 0.0150455 | DE12: 0.0151539 | DF12: 0.0152555 | DG12: 0.0153571 | DH12: 0.0154382 | DI12: 0.0155166 | DJ12: 0.0156028 | DK12: 0.0156635 | DL12: 0.0157221 | DM12: 0.0157869 | DN12: 0.015828 | DO12: 0.0158678 | DP12: 0.0159075 | DQ12: 0.0159258 | DR12: 0.015944 | DS12: 0.0159628

Sheet Diagram 1
B2: =Instructions!B3 -> Comparing Complex Deal Structures
B4: Deal Structure 1: Profit Sharing at the Joint Venture Level

Sheet Diagram 2
B2: =Instructions!B3 -> Comparing Complex Deal Structures
B4: Deal Structure 2: Profit Sharing at the Joint Venture Level

Sheet Scenario
B2: =Inputs!B2 -> Comparing Complex Deal Structures
E3: ="Vacancy Rate - "&E4 -> Vacancy Rate - Best Case
B4: Scenarios | C4: Scenario in Model | E4: =D9 -> Best Case
E7: Occupancy | K7: Transient ADR
B8: Label | C8: Case # | D8: Scenario In Model | E8: =C17 -> 2021 | F8: =D17 -> 2022 | G8: =E17 -> 2023 | H8: =F17 -> 2024 | I8: =G17 -> 2025 | J8: =H17 -> 2026 | K8: =I17 -> 2021 | L8: =J17 -> 2022 | ... Q8: =O17 -> Terminal Cap Rate
B9: Running Case in Model | C9: 1 | D9: =OFFSET(D$10,$C$9,0) -> Best Case | E9: =OFFSET(E$10,$C$9,0) -> 0.7 | F9: =OFFSET(F$10,$C$9,0) -> 0.75 | G9: =OFFSET(G$10,$C$9,0) -> 0.79 | H9: =OFFSET(H$10,$C$9,0) -> 0.81 | I9: =OFFSET(I$10,$C$9,0) -> 0.79 | J9: =OFFSET(J$10,$C$9,0) -> 0.8 | K9: =OFFSET(K$10,$C$9,0) -> 185 | ... Q9: =OFFSET(Q$10,$C$9,0) -> 0.085
E10: 3 | T10: =NOW() -> 46154.603
C11: 1 | D11: Best Case | E11: =VLOOKUP($D11,ScenarioTable,C$18,0) -> 0.7 | F11: =VLOOKUP($D11,ScenarioTable,D$18,0) -> 0.75 | G11: =VLOOKUP($D11,ScenarioTable,E$18,0) -> 0.79 | H11: =VLOOKUP($D11,ScenarioTable,F$18,0) -> 0.81 | I11: =VLOOKUP($D11,ScenarioTable,G$18,0) -> 0.79 | J11: =VLOOKUP($D11,ScenarioTable,H$18,0) -> 0.8 | K11: =VLOOKUP($D11,ScenarioTable,I$18,0) -> 185 | L11: =VLOOKUP($D11,ScenarioTable,J$18,0) -> 190 | ... Q11: =VLOOKUP($D11,ScenarioTable,O$18,0) -> 0.085 | S11: =C11 -> 1 | T11: 46154.603
C12: 2 | D12: Most Likely Case | E12: =VLOOKUP($D12,ScenarioTable,C$18,0) -> 0.69 | F12: =VLOOKUP($D12,ScenarioTable,D$18,0) -> 0.65 | G12: =VLOOKUP($D12,ScenarioTable,E$18,0) -> 0.6 | H12: =VLOOKUP($D12,ScenarioTable,F$18,0) -> 0.68 | I12: =VLOOKUP($D12,ScenarioTable,G$18,0) -> 0.71 | J12: =VLOOKUP($D12,ScenarioTable,H$18,0) -> 0.68 | K12: =VLOOKUP($D12,ScenarioTable,I$18,0) -> 180 | L12: =VLOOKUP($D12,ScenarioTable,J$18,0) -> 183 | ... Q12: =VLOOKUP($D12,ScenarioTable,O$18,0) -> 0.085 | S12: =C12 -> 2 | T12: 46154.603
C13: 3 | D13: Worst Case | E13: =VLOOKUP($D13,ScenarioTable,C$18,0) -> 0.68 | F13: =VLOOKUP($D13,ScenarioTable,D$18,0) -> 0.64 | G13: =VLOOKUP($D13,ScenarioTable,E$18,0) -> 0.59 | H13: =VLOOKUP($D13,ScenarioTable,F$18,0) -> 0.6 | I13: =VLOOKUP($D13,ScenarioTable,G$18,0) -> 0.62 | J13: =VLOOKUP($D13,ScenarioTable,H$18,0) -> 0.63 | K13: =VLOOKUP($D13,ScenarioTable,I$18,0) -> 175 | L13: =VLOOKUP($D13,ScenarioTable,J$18,0) -> 170 | ... Q13: =VLOOKUP($D13,ScenarioTable,O$18,0) -> 0.09 | S13: =C13 -> 3 | T13: 46154.603
T14: 46154.603
C16: Occupancy | I16: Transient ADR
B17: Scenario Table | C17: =Inputs!C22 -> 2021 | D17: =Inputs!D22 -> 2022 | E17: =Inputs!E22 -> 2023 | F17: =Inputs!F22 -> 2024 | G17: =Inputs!G22 -> 2025 | H17: =Inputs!H22 -> 2026 | I17: =C17 -> 2021 | J17: =D17 -> 2022 | K17: =E17 -> 2023 | L17: =F17 -> 2024 | M17: =G17 -> 2025 | N17: =H17 -> 2026 | O17: Terminal Cap Rate | P17: Probability of Scenario
B18: 1 | C18: =B18+1 -> 2 | D18: =C18+1 -> 3 | E18: =D18+1 -> 4 | F18: =E18+1 -> 5 | G18: =F18+1 -> 6 | H18: =G18+1 -> 7 | I18: =H18+1 -> 8 | J18: =I18+1 -> 9 | ... N18: =M18+1 -> 13 | O18: 14 | P18: a5
B19: Best Case | C19: 0.7 | D19: 0.75 | E19: 0.79 | F19: 0.81 | G19: 0.79 | H19: 0.8 | I19: 185 | J19: 190 | K19: 188 | L19: 185 | M19: 191 | N19: 192 | O19: 0.085 | P19: 0.35
B20: Most Likely Case | C20: 0.69 | D20: 0.65 | E20: 0.6 | F20: 0.68 | G20: 0.71 | H20: 0.68 | I20: 180 | J20: 183 | K20: 188 | L20: 185 | M20: 190 | N20: 195 | O20: 0.085 | P20: 0.5
B21: Worst Case | C21: 0.68 | D21: 0.64 | E21: 0.59 | F21: 0.6 | G21: 0.62 | H21: 0.63 | I21: 175 | J21: 170 | K21: 165 | L21: 165 | M21: 168 | N21: 170 | O21: 0.09 | P21: 0.15

Sheet Summary Analysis
B2: =Scenario!B2 -> Comparing Complex Deal Structures | H2: TO UPDATE DATA TABLES: F9
B4: Outputs | C4: Running Case | E4: =Scenario!C9 -> 1 | F4: 1
F5: 2
F6: 3
B7: Question 4: Data Tables
C9: 1
C10: 2
C11: 3
B12: Deal Structure 1 - Fulcrum Capital takes a preferred equity stake and Eagle Investments takes the LP Position.
C14: Net Equity Returns | F14: Co-Investor | I14: Sponsor - After Fees
C15: IRR | D15: CFx | E15: Net Profits | F15: IRR | G15: CFx | H15: Net Profits | I15: IRR | J15: CFx | K15: Net Profits
B16: Scenario | C16: ='Provided - CAP Acct. 1'!I121 -> 0.3335279 | D16: ='Provided - CAP Acct. 1'!I122 -> 2.9428465 | E16: ='Provided - CAP Acct. 1'!I123 -> 24229917 | F16: ='Q2 - Equity Waterfall 1'!E116 -> 0.22900502 | G16: ='Q2 - Equity Waterfall 1'!E117 -> 2.0323762 | H16: ='Q2 - Equity Waterfall 1'!E118 -> 11587612 | I16: ='Q2 - Equity Waterfall 1'!E126 -> 0.86798524 | J16: ='Q2 - Equity Waterfall 1'!E127 -> 12.735117 | K16: ='Q2 - Equity Waterfall 1'!E128 -> 13030711
B17: =Scenario!B19 -> Best Case | C17: =IF($E$4=$F4,$C$16,C17) -> 0.3335279 | D17: =IF($E$4=$F4,$D$16,D17) -> 2.9428465 | E17: =IF($E$4=$F4,$E$16,E17) -> 24229917 | F17: =IF($E$4=$F4,$F$16,F17) -> 0.22900502 | G17: =IF($E$4=$F4,$G$16,G17) -> 2.0323762 | H17: =IF($E$4=$F4,$H$16,H17) -> 11587612 | I17: =IF($E$4=$F4,$I$16,I17) -> 0.86798524 | J17: =IF($E$4=$F4,$J$16,J17) -> 12.735117 | K17: =IF($E$4=$F4,$K$16,K17) -> 13030711
B18: =Scenario!B20 -> Most Likely Case | C18: =IF($E$4=$F5,$C$16,C18) -> 0.13242428 | D18: =IF($E$4=$F5,$D$16,D18) -> 1.898842 | E18: =IF($E$4=$F5,$E$16,E18) -> 11209773 | F18: =IF($E$4=$F5,$F$16,F18) -> 0.094952723 | G18: =IF($E$4=$F5,$G$16,G18) -> 1.5683742 | H18: =IF($E$4=$F5,$H$16,H18) -> 6379554.2 | I18: =IF($E$4=$F5,$I$16,I18) -> 0.37545518 | J18: =IF($E$4=$F5,$J$16,J18) -> 5.8779076 | K18: =IF($E$4=$F5,$K$16,K18) -> 5416443.9
B19: =Scenario!B21 -> Worst Case | C19: =IF($E$4=$F6,$C$16,C19) -> -0.10244516 | D19: =IF($E$4=$F6,$D$16,D19) -> 0.5409178 | E19: =IF($E$4=$F6,$E$16,E19) -> -5859189.3 | F19: =IF($E$4=$F6,$F$16,F19) -> -0.085564022 | G19: =IF($E$4=$F6,$G$16,G19) -> 0.60101978 | H19: =IF($E$4=$F6,$H$16,H19) -> -4582906 | I19: =IF($E$4=$F6,$I$16,I19) -> -0.19872989 | J19: =IF($E$4=$F6,$J$16,J19) -> 0.44082445 | K19: =IF($E$4=$F6,$K$16,K19) -> -620910.28
B21: Expected Value | C21: =SUMPRODUCT(C17:C19,Probabilities) -> 0.16758013 | D21: =SUMPRODUCT(D17:D19,Probabilities) -> 2.060555 | E21: =SUMPRODUCT(E17:E19,Probabilities) -> 13206479 | F21: =SUMPRODUCT(F17:F19,Probabilities) -> 0.11479352 | G21: =SUMPRODUCT(G17:G19,Probabilities) -> 1.5856718 | H21: =SUMPRODUCT(H17:H19,Probabilities) -> 6558005.4 | I21: =SUMPRODUCT(I17:I19,Probabilities) -> 0.46171294 | J21: =SUMPRODUCT(J17:J19,Probabilities) -> 7.4623685 | K21: =SUMPRODUCT(K17:K19,Probabilities) -> 7175834.2
B23: Deal Structure 2 - SCP takes both a preferred equity AND Limited Partner (Co-Investor) stake.
C25: Net Equity Returns | F25: Co-Investor - After Pref Equity | I25: Sponsor - After Fees
C26: IRR | D26: CFx | E26: Net Profits | F26: IRR | G26: CFx | H26: Net Profits | I26: IRR | J26: CFx | K26: Net Profits
B27: Scenario | C27: ='Q1 - CAP Acct. 2'!I122 -> 0.36700209 | D27: ='Q1 - CAP Acct. 2'!I123 -> 2.8681056 | E27: ='Q1 - CAP Acct. 2'!I124 -> 23221117 | F27: ='Q3 - Equity Waterfall 2'!E145 -> 0.21543372 | G27: ='Q3 - Equity Waterfall 2'!E146 -> 1.8081024 | H27: ='Q3 - Equity Waterfall 2'!E147 -> 13016197 | I27: ='Q3 - Equity Waterfall 2'!E135 -> 0.94643975 | J27: ='Q3 - Equity Waterfall 2'!E136 -> 12.227224 | K27: ='Q3 - Equity Waterfall 2'!E137 -> 12390623
B28: =B17 -> Best Case | C28: =IF($E$4=$F4,$C$27,C28) -> 0.36700209 | D28: =IF($E$4=$F4,$D$27,D28) -> 2.8681056 | E28: =IF($E$4=$F4,$E$27,E28) -> 23221117 | F28: =IF($E$4=$F4,$F$27,F28) -> 0.21543372 | G28: =IF($E$4=$F4,$G$27,G28) -> 1.8081024 | H28: =IF($E$4=$F4,$H$27,H28) -> 13016197 | I28: =IF($E$4=$F4,$I$27,I28) -> 0.94643975 | J28: =IF($E$4=$F4,$J$27,J28) -> 12.227224 | K28: =IF($E$4=$F4,$K$27,K28) -> 12390623
B29: =B18 -> Most Likely Case | C29: =IF($E$4=$F5,$C$27,C29) -> 0.13001292 | D29: =IF($E$4=$F5,$D$27,D29) -> 1.8167195 | E29: =IF($E$4=$F5,$E$27,E29) -> 10152070 | F29: =IF($E$4=$F5,$F$27,F29) -> 0.10351493 | G29: =IF($E$4=$F5,$G$27,G29) -> 1.5110477 | H29: =IF($E$4=$F5,$H$27,H29) -> 8231502.9 | I29: =IF($E$4=$F5,$I$27,I29) -> 0.36594853 | J29: =IF($E$4=$F5,$J$27,J29) -> 5.0084828 | K29: =IF($E$4=$F5,$K$27,K29) -> 4423853.8
B30: =B19 -> Worst Case | C30: =IF($E$4=$F6,$C$27,C30) -> -0.15412311 | D30: =IF($E$4=$F6,$D$27,D30) -> 0.41458989 | E30: =IF($E$4=$F6,$E$27,E30) -> -7447462 | F30: =IF($E$4=$F6,$F$27,F30) -> -0.051213007 | G30: =IF($E$4=$F6,$G$27,G30) -> 0.78986162 | H30: =IF($E$4=$F6,$H$27,H30) -> -3384722.8 | I30: =IF($E$4=$F6,$I$27,I30) -> -0.22866605 | J30: =IF($E$4=$F6,$J$27,J30) -> 0.40489895 | K30: =IF($E$4=$F6,$K$27,K30) -> -656767.2
B32: Expected Value | C32: =SUMPRODUCT(C28:C30,Probabilities) -> 0.17033873 | D32: =SUMPRODUCT(D28:D30,Probabilities) -> 1.9743852 | E32: =SUMPRODUCT(E28:E30,Probabilities) -> 12086307 | F32: =SUMPRODUCT(F28:F30,Probabilities) -> 0.11947732 | G32: =SUMPRODUCT(G28:G30,Probabilities) -> 1.5068389 | H32: =SUMPRODUCT(H28:H30,Probabilities) -> 8163711.9 | I32: =SUMPRODUCT(I28:I30,Probabilities) -> 0.47992827 | J32: =SUMPRODUCT(J28:J30,Probabilities) -> 6.8445047 | K32: =SUMPRODUCT(K28:K30,Probabilities) -> 6450129.8
B34: Question 5: Comparing Net Equity Returns
B36: Capital Structure Analysis - Risk Adjusted Returns
B38: =B12 -> Deal Structure 1 - Fulcrum Capital takes a preferred equity stake and Eagle Investments takes the LP Position.
B40: Scenario | C40: Returns | D40: Probability | E40: Deviation | F40: Sq. Deviation | G40: Product
B41: =B17 -> Best Case | C41: =C17 -> 0.3335279 | D41: =Scenario!P19 -> 0.35 | E41: =C41-$C$44 -> 0.16594777 | F41: =E41^2 -> 0.027538663 | G41: =D41*F41 -> 0.0096385322
B42: =B18 -> Most Likely Case | C42: =C18 -> 0.13242428 | D42: =Scenario!P20 -> 0.5 | E42: =C42-$C$44 -> -0.035155855 | F42: =E42^2 -> 0.0012359341 | G42: =D42*F42 -> 0.00061796706
B43: =B19 -> Worst Case | C43: =C19 -> -0.10244516 | D43: =Scenario!P21 -> 0.15 | E43: =C43-$C$44 -> -0.27002529 | F43: =E43^2 -> 0.072913657 | G43: =D43*F43 -> 0.010937048
B44: Expected Returns | C44: =SUMPRODUCT(C41:C43,D41:D43) -> 0.16758013
B45: Standard Deviation | C45: =SQRT(SUM(G41:G43)) -> 0.14558004
B46: Returns per Unit of Risk | C46: =C44/C45 -> 1.1511203
B48: =B23 -> Deal Structure 2 - SCP takes both a preferred equity AND Limited Partner (Co-Investor) stake.
B50: Scenario | C50: Returns | D50: Probability | E50: Deviation | F50: Sq. Deviation | G50: Product
B51: =B41 -> Best Case | C51: =C28 -> 0.36700209 | D51: =Scenario!P19 -> 0.35 | E51: =C51-$C$54 -> 0.19666336 | F51: =E51^2 -> 0.038676478 | G51: =D51*F51 -> 0.013536767
B52: =B42 -> Most Likely Case | C52: =C29 -> 0.13001292 | D52: =Scenario!P20 -> 0.5 | E52: =C52-$C$54 -> -0.040325803 | F52: =E52^2 -> 0.0016261704 | G52: =D52*F52 -> 0.00081308519
B53: =B43 -> Worst Case | C53: =C30 -> -0.15412311 | D53: =Scenario!P21 -> 0.15 | E53: =C53-$C$54 -> -0.32446183 | F53: =E53^2 -> 0.10527548 | G53: =D53*F53 -> 0.015791322
B54: Expected Returns | C54: =SUMPRODUCT(C51:C53,D51:D53) -> 0.17033873
...

Sheet NOI
B2: =Inputs!B2 -> Comparing Complex Deal Structures
B4: Model: Pro-Forma - Hotel | C4: Scenario in Model: | E4: =Scenario!E4 -> Best Case
C7: Years | K7: =C8 -> 2021 | O7: =D8 -> 2022 | S7: =E8 -> 2023 | W7: =F8 -> 2024 | AA7: =G8 -> 2025 | AE7: =H8 -> 2026
C8: =Inputs!C22 -> 2021 | D8: =Inputs!D22 -> 2022 | E8: =Inputs!E22 -> 2023 | F8: =Inputs!F22 -> 2024 | G8: =Inputs!G22 -> 2025 | H8: =Inputs!H22 -> 2026 | K8: % | L8: PAR | M8: POR | O8: % | P8: PAR | Q8: POR | S8: % | T8: PAR | U8: POR | W8: % | X8: PAR | Y8: POR | AA8: % | AB8: PAR | AC8: POR | AE8: % | AF8: PAR | AG8: POR
C9: 1 | D9: =C9+1 -> 2 | E9: =D9+1 -> 3 | F9: =E9+1 -> 4 | G9: =F9+1 -> 5 | H9: =G9+1 -> 6
B10: Inflation Adjustment | C10: {=PRODUCT(1+Inputs!$C$32:C32)} -> 1.02 | D10: {=PRODUCT(1+Inputs!$C$32:D32)} -> 1.0404 | E10: {=PRODUCT(1+Inputs!$C$32:E32)} -> 1.061208 | F10: {=PRODUCT(1+Inputs!$C$32:F32)} -> 1.0824322 | G10: {=PRODUCT(1+Inputs!$C$32:G32)} -> 1.1040808 | H10: {=PRODUCT(1+Inputs!$C$32:H32)} -> 1.1261624 | I10: x
B11: Hotel Revenue
B12: Rooms | C12: =SUMPRODUCT(C17:C18,C21:C22) -> 10667125 | D12: =SUMPRODUCT(D17:D18,D21:D22) -> 11757562 | E12: =SUMPRODUCT(E17:E18,E21:E22) -> 12157557 | F12: =SUMPRODUCT(F17:F18,F21:F22) -> 12565125 | G12: =SUMPRODUCT(G17:G18,G21:G22) -> 12600895 | H12: =SUMPRODUCT(H17:H18,H21:H22) -> 13205700 | I12: x | K12: =C12/C$31 -> 0.72773226 | L12: =C12/C$15 -> 116.9 | M12: =C12/C$16 -> 167 | O12: =D12/D$31 -> 0.7393954 | P12: =D12/D$15 -> 128.85 | Q12: =D12/D$16 -> 171.8 | S12: =E12/E$31 -> 0.71697006 | T12: =E12/E$15 -> 133.2335 | U12: =E12/E$16 -> 168.65 | W12: =F12/F$31 -> 0.68218299 | X12: =F12/F$15 -> 137.7 | Y12: =F12/F$16 -> 170 | AA12: =G12/G$31 -> 0.71448425 | AB12: =G12/G$15 -> 138.092 | AC12: =G12/G$16 -> 174.8 | AE12: =H12/H$31 -> 0.74470187 | AF12: =H12/H$15 -> 144.72 | AG12: =H12/H$16 -> 180.9
B13: Number of Rooms | C13: =NumberRooms -> 250 | D13: =NumberRooms -> 250 | E13: =NumberRooms -> 250 | F13: =NumberRooms -> 250 | G13: =NumberRooms -> 250 | H13: =NumberRooms -> 250 | I13: x
B14: Days Open | C14: =DaysOpen -> 365 | D14: =DaysOpen -> 365 | E14: =DaysOpen -> 365 | F14: =DaysOpen -> 365 | G14: =DaysOpen -> 365 | H14: =DaysOpen -> 365 | I14: x
B15: Annual Available Rooms | C15: =C13*C14 -> 91250 | D15: =D13*D14 -> 91250 | E15: =E13*E14 -> 91250 | F15: =F13*F14 -> 91250 | G15: =G13*G14 -> 91250 | H15: =H13*H14 -> 91250 | I15: x
B16: Occupied Rooms | C16: =SUM(C17:C18) -> 63875 | D16: =SUM(D17:D18) -> 68437.5 | E16: =SUM(E17:E18) -> 72087.5 | F16: =SUM(F17:F18) -> 73912.5 | G16: =SUM(G17:G18) -> 72087.5 | H16: =SUM(H17:H18) -> 73000 | I16: x
B17: Transient Occupied Rooms | C17: =C$15*Inputs!C$23*Inputs!C24 -> 38325 | D17: =D$15*Inputs!D$23*Inputs!D24 -> 44484.375 | E17: =E$15*Inputs!E$23*Inputs!E24 -> 39648.125 | F17: =F$15*Inputs!F$23*Inputs!F24 -> 29565 | G17: =G$15*Inputs!G$23*Inputs!G24 -> 39648.125 | H17: =H$15*Inputs!H$23*Inputs!H24 -> 51100 | I17: x
B18: Group Occupied Rooms | C18: =C$15*Inputs!C$23*Inputs!C25 -> 25550 | D18: =D$15*Inputs!D$23*Inputs!D25 -> 23953.125 | E18: =E$15*Inputs!E$23*Inputs!E25 -> 32439.375 | F18: =F$15*Inputs!F$23*Inputs!F25 -> 44347.5 | G18: =G$15*Inputs!G$23*Inputs!G25 -> 32439.375 | H18: =H$15*Inputs!H$23*Inputs!H25 -> 21900 | I18: x
B19: Occupancy | C19: =C16/C15 -> 0.7 | D19: =D16/D15 -> 0.75 | E19: =E16/E15 -> 0.79 | F19: =F16/F15 -> 0.81 | G19: =G16/G15 -> 0.79 | H19: =H16/H15 -> 0.8 | I19: x
B20: Average Rate (ADR) | C20: =Inputs!C26 -> 164 | D20: =Inputs!D26 -> 167.25 | E20: =Inputs!E26 -> 168.65 | F20: =Inputs!F26 -> 170 | G20: =Inputs!G26 -> 174.25 | H20: =Inputs!H26 -> 183 | I20: x
B21: ADR Transient | C21: =Inputs!C27 -> 185 | D21: =Inputs!D27 -> 190 | E21: =Inputs!E27 -> 188 | F21: =Inputs!F27 -> 185 | G21: =Inputs!G27 -> 191 | H21: =Inputs!H27 -> 192 | I21: x
B22: ADR Group | C22: =Inputs!C28 -> 140 | D22: =Inputs!D28 -> 138 | E22: =Inputs!E28 -> 145 | F22: =Inputs!F28 -> 160 | G22: =Inputs!G28 -> 155 | H22: =Inputs!H28 -> 155 | I22: x
B23: % Change | D23: =(D20/C20)-1 -> 0.019817073 | E23: =(E20/D20)-1 -> 0.0083707025 | F23: =(F20/E20)-1 -> 0.0080047436 | G23: =(G20/F20)-1 -> 0.025 | H23: =(H20/G20)-1 -> 0.050215208 | I23: x
B24: RevPAR | C24: =C19*C20 -> 114.8 | D24: =D19*D20 -> 125.4375 | E24: =E19*E20 -> 133.2335 | F24: =F19*F20 -> 137.7 | G24: =G19*G20 -> 137.6575 | H24: =H19*H20 -> 146.4 | I24: x
B25: % Change | D25: =(D24/C24)-1 -> 0.09266115 | E25: =(E24/D24)-1 -> 0.062150473 | F25: =(F24/E24)-1 -> 0.033523851 | G25: =(G24/F24)-1 -> -0.00030864198 | H25: =(H24/G24)-1 -> 0.063509071 | I25: x
B26: Total F&B | C26: =SUM(C27:C28) -> 3564225 | D26: =SUM(D27:D28) -> 3673725 | E26: =SUM(E27:E28) -> 4312995.1 | F26: =SUM(F27:F28) -> 5351265 | G26: =SUM(G27:G28) -> 4531420.2 | H26: =SUM(H27:H28) -> 3998940 | I26: x | K26: =C26/C$31 -> 0.24315845 | L26: =C26/C$15 -> 39.06 | M26: =C26/C$16 -> 55.8 | O26: =D26/D$31 -> 0.23102878 | P26: =D26/D$15 -> 40.26 | Q26: =D26/D$16 -> 53.68 | S26: =E26/E$31 -> 0.25435113 | T26: =E26/E$15 -> 47.2657 | U26: =E26/E$16 -> 59.83 | W26: =F26/F$31 -> 0.2905297 | X26: =F26/F$15 -> 58.644 | Y26: =F26/F$16 -> 72.4 | AA26: =G26/G$31 -> 0.25693638 | AB26: =G26/G$15 -> 49.6594 | AC26: =G26/G$16 -> 62.86 | AE26: =H26/H$31 -> 0.22551005 | AF26: =H26/H$15 -> 43.824 | AG26: =H26/H$16 -> 54.78
B27: FB Transient | C27: =C17*C21*Inputs!C30 -> 1418025 | D27: =D17*D21*Inputs!D30 -> 1690406.2 | E27: =E17*E21*Inputs!E30 -> 1490769.5 | F27: =F17*F21*Inputs!F30 -> 1093905 | G27: =G17*G21*Inputs!G30 -> 1514558.4 | H27: =H17*H21*Inputs!H30 -> 1962240 | I27: x
B28: FB Group | C28: =C18*C22*Inputs!C31 -> 2146200 | D28: =D18*D22*Inputs!D31 -> 1983318.8 | E28: =E18*E22*Inputs!E31 -> 2822225.6 | F28: =F18*F22*Inputs!F31 -> 4257360 | G28: =G18*G22*Inputs!G31 -> 3016861.9 | H28: =H18*H22*Inputs!H31 -> 2036700 | I28: x
B29: Miscellaneous | C29: =C12*MiscRate -> 426685 | D29: =D12*MiscRate -> 470302.5 | E29: =E12*MiscRate -> 486302.28 | F29: =F12*MiscRate -> 502605 | G29: =G12*MiscRate -> 504035.8 | H29: =H12*MiscRate -> 528228 | I29: x | K29: =C29/C$31 -> 0.029109291 | L29: =C29/C$15 -> 4.676 | M29: =C29/C$16 -> 6.68 | O29: =D29/D$31 -> 0.029575816 | P29: =D29/D$15 -> 5.154 | Q29: =D29/D$16 -> 6.872 | S29: =E29/E$31 -> 0.028678803 | T29: =E29/E$15 -> 5.32934 | U29: =E29/E$16 -> 6.746 | W29: =F29/F$31 -> 0.027287319 | X29: =F29/F$15 -> 5.508 | Y29: =F29/F$16 -> 6.8 | AA29: =G29/G$31 -> 0.02857937 | AB29: =G29/G$15 -> 5.52368 | AC29: =G29/G$16 -> 6.992 | AE29: =H29/H$31 -> 0.029788075 | AF29: =H29/H$15 -> 5.7888 | AG29: =H29/H$16 -> 7.236
B31: Total Hotel Revenue | C31: =SUM(C12,C26,C29) -> 14658035 | D31: =SUM(D12,D26,D29) -> 15901590 | E31: =SUM(E12,E26,E29) -> 16956854 | F31: =SUM(F12,F26,F29) -> 18418995 | G31: =SUM(G12,G26,G29) -> 17636351 | H31: =SUM(H12,H26,H29) -> 17732868 | I31: x
B33: Effective Gross Income (EGI) | C33: =SUM(C31) -> 14658035 | D33: =SUM(D31) -> 15901590 | E33: =SUM(E31) -> 16956854 | F33: =SUM(F31) -> 18418995 | G33: =SUM(G31) -> 17636351 | H33: =SUM(H31) -> 17732868 | I33: x | K33: =C33/C$31 -> 1 | L33: =C33/C$15 -> 160.636 | M33: =C33/C$16 -> 229.48 | O33: =D33/D$31 -> 1 | P33: =D33/D$15 -> 174.264 | Q33: =D33/D$16 -> 232.352 | S33: =E33/E$31 -> 1 | T33: =E33/E$15 -> 185.82854 | U33: =E33/E$16 -> 235.226 | W33: =F33/F$31 -> 1 | X33: =F33/F$15 -> 201.852 | Y33: =F33/F$16 -> 249.2 | AA33: =G33/G$31 -> 1 | AB33: =G33/G$15 -> 193.27508 | AC33: =G33/G$16 -> 244.652 | AE33: =H33/H$31 -> 1 | AF33: =H33/H$15 -> 194.3328 | AG33: =H33/H$16 -> 242.916
B35: Operating Expenses
B36: DISTRIBUTED
B37: Rooms | C37: =C$12*Inputs!$J61+(Inputs!$H61*C$15+Inputs!$I61*C$16)*C$10 -> 3225738.6 | D37: =D$12*Inputs!$J61+(Inputs!$H61*D$15+Inputs!$I61*D$16)*D$10 -> 3495693.7 | E37: =E$12*Inputs!$J61+(Inputs!$H61*E$15+Inputs!$I61*E$16)*E$10 -> 3634090.9 | F37: =F$12*Inputs!$J61+(Inputs!$H61*F$15+Inputs!$I61*F$16)*F$10 -> 3756161.6 | G37: =G$12*Inputs!$J61+(Inputs!$H61*G$15+Inputs!$I61*G$16)*G$10 -> 3772299.2 | H37: =H$12*Inputs!$J61+(Inputs!$H61*H$15+Inputs!$I61*H$16)*H$10 -> 3921543.7 | I37: x | K37: =C37/C$12 -> 0.3024 | L37: =C37/C$15 -> 35.35056 | M37: =C37/C$16 -> 50.5008 | O37: =D37/D$12 -> 0.29731449 | P37: =D37/D$15 -> 38.308972 | Q37: =D37/D$16 -> 51.078629 | S37: =E37/E$12 -> 0.29891621 | T37: =E37/E$15 -> 39.825653 | U37: =E37/E$16 -> 50.412219 | W37: =F37/F$12 -> 0.29893548 | X37: =F37/F$15 -> 41.163415 | Y37: =F37/F$16 -> 50.819031 | AA37: =G37/G$12 -> 0.29936756 | AB37: =G37/G$15 -> 41.340266 | AC37: =G37/G$16 -> 52.32945 | AE37: =H37/H$12 -> 0.29695841 | AF37: =H37/H$15 -> 42.975821 | AG37: =H37/H$16 -> 53.719776
B38: Total F&B | C38: =C$26*Inputs!$J62+(Inputs!$H62*C$15+Inputs!$I62*C$16)*C$10 -> 2862785.5 | D38: =D$26*Inputs!$J62+(Inputs!$H62*D$15+Inputs!$I62*D$16)*D$10 -> 2944499.2 | E38: =E$26*Inputs!$J62+(Inputs!$H62*E$15+Inputs!$I62*E$16)*E$10 -> 3365498.3 | F38: =F$26*Inputs!$J62+(Inputs!$H62*F$15+Inputs!$I62*F$16)*F$10 -> 4042094.7 | G38: =G$26*Inputs!$J62+(Inputs!$H62*G$15+Inputs!$I62*G$16)*G$10 -> 3529739.7 | H38: =H$26*Inputs!$J62+(Inputs!$H62*H$15+Inputs!$I62*H$16)*H$10 -> 3201545 | I38: x | K38: =C38/C$26 -> 0.8032 | L38: =C38/C$15 -> 31.372992 | M38: =C38/C$16 -> 44.81856 | O38: =D38/D$26 -> 0.80150233 | P38: =D38/D$15 -> 32.268484 | Q38: =D38/D$16 -> 43.024645 | S38: =E38/E$26 -> 0.78031582 | T38: =E38/E$15 -> 36.882174 | U38: =E38/E$16 -> 46.686296 | W38: =F38/F$26 -> 0.75535311 | X38: =F38/F$15 -> 44.296928 | Y38: =F38/F$16 -> 54.687565 | AA38: =G38/G$26 -> 0.77894778 | AB38: =G38/G$15 -> 38.682079 | AC38: =G38/G$16 -> 48.964657 | AE38: =H38/H$26 -> 0.80059841 | AF38: =H38/H$15 -> 35.085425 | AG38: =H38/H$16 -> 43.856781
B39: Miscellaneous | C39: =C$29*Inputs!$J63+(Inputs!$H63*C$15+Inputs!$I63*C$16)*C$10 -> 299874.22 | D39: =D$29*Inputs!$J63+(Inputs!$H63*D$15+Inputs!$I63*D$16)*D$10 -> 325518.63 | E39: =E$29*Inputs!$J63+(Inputs!$H63*E$15+Inputs!$I63*E$16)*E$10 -> 335721.49 | F39: =F$29*Inputs!$J63+(Inputs!$H63*F$15+Inputs!$I63*F$16)*F$10 -> 346118.86 | G39: =G$29*Inputs!$J63+(Inputs!$H63*G$15+Inputs!$I63*G$16)*G$10 -> 348213.31 | H39: =H$29*Inputs!$J63+(Inputs!$H63*H$15+Inputs!$I63*H$16)*H$10 -> 363080.01 | I39: x | K39: =C39/C$29 -> 0.7028 | L39: =C39/C$15 -> 3.2862928 | M39: =C39/C$16 -> 4.694704 | O39: =D39/D$29 -> 0.69214735 | P39: =D39/D$15 -> 3.5673275 | Q39: =D39/D$16 -> 4.7564366 | S39: =E39/E$29 -> 0.69035558 | T39: =E39/E$15 -> 3.6791396 | U39: =E39/E$16 -> 4.6571387 | W39: =F39/F$29 -> 0.68864985 | X39: =F39/F$15 -> 3.7930834 | Y39: =F39/F$16 -> 4.682819 | AA39: =G39/G$29 -> 0.69085035 | AB39: =G39/G$15 -> 3.8160363 | AC39: =G39/G$16 -> 4.8304256 | AE39: =H39/H$29 -> 0.68735471 | AF39: =H39/H$15 -> 3.978959 | AG39: =H39/H$16 -> 4.9736987
B40: TOTAL DEPT EXPENSE | C40: =SUM(C37:C39) -> 6388398.3 | D40: =SUM(D37:D39) -> 6765711.4 | E40: =SUM(E37:E39) -> 7335310.7 | F40: =SUM(F37:F39) -> 8144375.2 | G40: =SUM(G37:G39) -> 7650252.3 | H40: =SUM(H37:H39) -> 7486168.7 | I40: x | K40: =C40/C33 -> 0.43582911 | L40: =C40/C$15 -> 70.009845 | M40: =C40/C$16 -> 100.01406 | O40: =D40/D33 -> 0.4254739 | P40: =D40/D$15 -> 74.144783 | Q40: =D40/D$16 -> 98.859711 | S40: =E40/E33 -> 0.43258676 | T40: =E40/E$15 -> 80.386966 | U40: =E40/E$16 -> 101.75565 | W40: =F40/F33 -> 0.44217261 | X40: =F40/F$15 -> 89.253426 | Y40: =F40/F$16 -> 110.18942 | AA40: =G40/G33 -> 0.4337775 | AB40: =G40/G$15 -> 83.838381 | AC40: =G40/G$16 -> 106.12453 | AE40: =H40/H33 -> 0.42216345 | AF40: =H40/H$15 -> 82.040205 | AG40: =H40/H$16 -> 102.55026
B42: PROFIT
B43: Rooms | C43: =C12-C37 -> 7441386.4 | D43: =D12-D37 -> 8261868.8 | E43: =E12-E37 -> 8523466 | F43: =F12-F37 -> 8808963.4 | G43: =G12-G37 -> 8828595.8 | H43: =H12-H37 -> 9284156.3 | I43: x | K43: =1-K37 -> 0.6976 | L43: =C43/C$15 -> 81.54944 | M43: =C43/C$16 -> 116.4992 | O43: =1-O37 -> 0.70268551 | P43: =D43/D$15 -> 90.541028 | Q43: =D43/D$16 -> 120.72137 | S43: =1-S37 -> 0.70108379 | T43: =E43/E$15 -> 93.407847 | U43: =E43/E$16 -> 118.23778 | W43: =1-W37 -> 0.70106452 | X43: =F43/F$15 -> 96.536585 | Y43: =F43/F$16 -> 119.18097 | AA43: =1-AA37 -> 0.70063244 | AB43: =G43/G$15 -> 96.751734 | AC43: =G43/G$16 -> 122.47055 | AE43: =1-AE37 -> 0.70304159 | AF43: =H43/H$15 -> 101.74418 | AG43: =H43/H$16 -> 127.18022
B44: Total F&B | C44: =C26-C38 -> 701439.48 | D44: =D26-D38 -> 729225.85 | E44: =E26-E38 -> 947496.79 | F44: =F26-F38 -> 1309170.3 | G44: =G26-G38 -> 1001680.5 | H44: =H26-H38 -> 797395 | I44: x | K44: =1-K38 -> 0.1968 | L44: =C44/C$15 -> 7.687008 | M44: =C44/C$16 -> 10.98144 | O44: =1-O38 -> 0.19849767 | P44: =D44/D$15 -> 7.9915162 | Q44: =D44/D$16 -> 10.655355 | S44: =1-S38 -> 0.21968418 | T44: =E44/E$15 -> 10.383526 | U44: =E44/E$16 -> 13.143704 | W44: =1-W38 -> 0.24464689 | X44: =F44/F$15 -> 14.347072 | Y44: =F44/F$16 -> 17.712435 | AA44: =1-AA38 -> 0.22105222 | AB44: =G44/G$15 -> 10.977321 | AC44: =G44/G$16 -> 13.895343 | AE44: =1-AE38 -> 0.19940159 | AF44: =H44/H$15 -> 8.7385753 | AG44: =H44/H$16 -> 10.923219
B45: Miscellaneous | C45: =C29-C39 -> 126810.78 | D45: =D29-D39 -> 144783.87 | E45: =E29-E39 -> 150580.79 | F45: =F29-F39 -> 156486.14 | G45: =G29-G39 -> 155822.49 | H45: =H29-H39 -> 165147.99 | I45: x | K45: =1-K39 -> 0.2972 | L45: =C45/C$15 -> 1.3897072 | M45: =C45/C$16 -> 1.985296 | O45: =1-O39 -> 0.30785265 | P45: =D45/D$15 -> 1.5866725 | Q45: =D45/D$16 -> 2.1155634 | S45: =1-S39 -> 0.30964442 | T45: =E45/E$15 -> 1.6502004 | U45: =E45/E$16 -> 2.0888613 | W45: =1-W39 -> 0.31135015 | X45: =F45/F$15 -> 1.7149166 | Y45: =F45/F$16 -> 2.117181 | AA45: =1-AA39 -> 0.30914965 | AB45: =G45/G$15 -> 1.7076437 | AC45: =G45/G$16 -> 2.1615744 | AE45: =1-AE39 -> 0.31264529 | AF45: =H45/H$15 -> 1.809841 | AG45: =H45/H$16 -> 2.2623013
B46: TOTAL DEPT PROFIT | C46: =SUM(C43:C45) -> 8269636.7 | D46: =SUM(D43:D45) -> 9135878.6 | E46: =SUM(E43:E45) -> 9621543.6 | F46: =SUM(F43:F45) -> 10274620 | G46: =SUM(G43:G45) -> 9986098.8 | H46: =SUM(H43:H45) -> 10246699 | I46: x | K46: =C46/C$33 -> 0.56417089 | L46: =C46/C$15 -> 90.626155 | M46: =C46/C$16 -> 129.46594 | O46: =D46/D$33 -> 0.5745261 | P46: =D46/D$15 -> 100.11922 | Q46: =D46/D$16 -> 133.49229 | S46: =E46/E$33 -> 0.56741324 | T46: =E46/E$15 -> 105.44157 | U46: =E46/E$16 -> 133.47035 | W46: =F46/F$33 -> 0.55782739 | X46: =F46/F$15 -> 112.59857 | Y46: =F46/F$16 -> 139.01058 | AA46: =G46/G$33 -> 0.5662225 | AB46: =G46/G$15 -> 109.4367 | AC46: =G46/G$16 -> 138.52747 | AE46: =H46/H$33 -> 0.57783655 | AF46: =H46/H$15 -> 112.2926 | AG46: =H46/H$16 -> 140.36574
B48: UNDISTRIBUTED
B49: Administrative & General | C49: =C$33*Inputs!$J68+(Inputs!$H68*C$15+Inputs!$I68*C$16)*C$10 -> 1486324.7 | D49: =D$33*Inputs!$J68+(Inputs!$H68*D$15+Inputs!$I68*D$16)*D$10 -> 1544563.1 | E49: =E$33*Inputs!$J68+(Inputs!$H68*E$15+Inputs!$I68*E$16)*E$10 -> 1597571.3 | F49: =F$33*Inputs!$J68+(Inputs!$H68*F$15+Inputs!$I68*F$16)*F$10 -> 1663212.8 | G49: =G$33*Inputs!$J68+(Inputs!$H68*G$15+Inputs!$I68*G$16)*G$10 -> 1661946.4 | H49: =H$33*Inputs!$J68+(Inputs!$H68*H$15+Inputs!$I68*H$16)*H$10 -> 1687499 | I49: x | K49: =C49/C$33 -> 0.1014 | L49: =C49/C$15 -> 16.28849 | M49: =C49/C$16 -> 23.269272 | O49: =D49/D$33 -> 0.097132618 | P49: =D49/D$15 -> 16.926719 | Q49: =D49/D$16 -> 22.568958 | S49: =E49/E$33 -> 0.094213896 | T49: =E49/E$15 -> 17.507631 | U49: =E49/E$16 -> 22.161558 | W49: =F49/F$33 -> 0.090298784 | X49: =F49/F$15 -> 18.22699 | Y49: =F49/F$16 -> 22.502457 | AA49: =G49/G$33 -> 0.094234141 | AB49: =G49/G$15 -> 18.213111 | AC49: =G49/G$16 -> 23.054571 | AE49: =H49/H$33 -> 0.095162216 | AF49: =H49/H$15 -> 18.49314 | AG49: =H49/H$16 -> 23.116425
...

Sheet Valuation
B2: =Inputs!B2 -> Comparing Complex Deal Structures
B4: Model: Valuation | C4: Scenario in Model: | E4: =Scenario!E4 -> Best Case
C7: Years
C8: =NOI!C8 -> 2021 | D8: =NOI!D8 -> 2022 | E8: =NOI!E8 -> 2023 | F8: =NOI!F8 -> 2024 | G8: =NOI!G8 -> 2025 | H8: =NOI!H8 -> 2026
B9: 0 | C9: 1 | D9: =C9+1 -> 2 | E9: =D9+1 -> 3 | F9: =E9+1 -> 4 | G9: =F9+1 -> 5 | H9: =G9+1 -> 6
B10: =NOI!B76 -> Before Debt Service Cash Flow (BDSCF)
B11: Hotel | C11: =NOI!C76 -> 2957564.8 | D11: =NOI!D76 -> 3538755.8 | E11: =NOI!E76 -> 3772830.2 | F11: =NOI!F76 -> 4115574.6 | G11: =NOI!G76 -> 3902006.4 | H11: =NOI!H76 -> 4077745.3 | I11: x
B13: Present Value Factor
B14: ="Hotel at "&TEXT(DiscountRateHotel,"0.00%") -> Hotel at 10.00% | C14: =1/(1+DiscountRateHotel)^C9 -> 0.90909091 | D14: =1/(1+DiscountRateHotel)^D9 -> 0.82644628 | E14: =1/(1+DiscountRateHotel)^E9 -> 0.7513148 | F14: =1/(1+DiscountRateHotel)^F9 -> 0.68301346 | G14: =1/(1+DiscountRateHotel)^G9 -> 0.62092132 | I14: x
B16: Present Value of Cash Flow
B17: Hotel | C17: =C11*C14 -> 2688695.3 | D17: =D11*D14 -> 2924591.6 | E17: =E11*E14 -> 2834583.1 | F17: =F11*F14 -> 2810992.8 | G17: =G11*G14 -> 2422839 | I17: x
B19: Resale Calculations:
B20: Hotel (as of the end of Yr. 5) | G20: =NOI!H76/TerminalCapRateHotel -> 47973474 | I20: x
B22: Selling Cost
B23: Hotel | G23: =G20*SellingCost -> 1439204.2 | I23: x
B25: Net Resale
B26: Hotel | G26: =G20-G23 -> 46534270 | I26: x
B29: Unlevered Value
B30: Hotel | D30: Share
B31: PV Cash flows | C31: =SUM(C17:G17) -> 13681702 | D31: =C31/$C$33 -> 0.32134909
B32: PV of Reversion | C32: =G26*G14 -> 28894121 | D32: =C32/$C$33 -> 0.67865091
B33: Total Unlevered Value | C33: =SUM(C31:C32) -> 42575822 | D33: =SUM(D31:D32) -> 1
B34: Unlevered Value Per Key | C34: =C33/NumberRooms -> 170303.29

Sheet Provided - CAP Acct. 1
F2: =Inputs!B2 -> Comparing Complex Deal Structures
F4: Model: Capital Accounts | I4: Scenario in Model: | K4: =Scenario!E4 -> Best Case | M4: Deal in Model: | O4: Case 1 - Eagle Investment & Fulcrum Capital
F6: SOURCES AND USES | O6: FINANCING ASSUMPTIONS
F8: USES | H8: $ | I8: Per Key | J8: SOURCES | L8: $ | M8: % | O8: CONSTRUCTION LOAN | S8: PERMANENT LOAN
F9: Land | H9: 5000000 | I9: =H9/NumberRooms -> 20000 | J9: Construction Loan | L9: =ConstLoanOBalance -> 12500000 | M9: =L9/H15 -> 0.42165409 | O9: Construction Loan Commitment | R9: 12500000 | S9: Permanent Loan Proceeds | V9: =V10/V11/V15 -> 35005242
F10: Soft Costs | H10: =SUM(Construction!D10:D13)+Construction!D26 -> 4600000 | I10: =H10/NumberRooms -> 18400 | J10: Preferred Equity | L10: =PreferredEquityOBalance -> 5000000 | M10: =L10/$H$15 -> 0.16866164 | O10: Loan Fees | R10: 0.01 | S10: NOI at Refi | V10: =INDEX($I$36:$CO$36,MATCH(V16,$I$28:$CO$28,FALSE)) -> 3772830.2
F11: Hard Costs | H11: =SUM(Construction!D14:D15,Construction!D25) -> 17570000 | I11: =H11/NumberRooms -> 70280 | J11: Common Equity | L11: =TotalUses-SUM(L9:L10) -> 12145153 | M11: =L11/$H$15 -> 0.40968427 | O11: Spread | R11: 0.045 | S11: DSCR | V11: 1.35
F12: Contingency and Escalation | H12: =SUM(Construction!D29:D30) -> 1350153 | I12: =H12/NumberRooms -> 5400.612 | J12: Sponsor | L12: =M12*$L$11 -> 1214515.3 | M12: 0.1 | O12: Origination | R12: =H18 -> 44196 | S12: Loan Fees | V12: 0.01
F13: Interest Reserve | H13: 1000000 | I13: =H13/NumberRooms -> 4000 | J13: Co-Investor | L13: =M13*$L$11 -> 10930638 | M13: =1-M12 -> 0.9 | O13: Maturity | Q13: 3 | R13: =EOMONTH(R12,Q13*12) -> 45291 | S13: Rate | V13: 0.07
F14: Loan Fees | H14: =R10*L9 -> 125000 | I14: =H14/NumberRooms -> 500 | O14: Type | R14: 360 | S14: Amortization (Years) | V14: 30
F15: Total Uses | H15: =SUM(H9:H14) -> 29645153 | I15: =H15/NumberRooms -> 118580.61 | J15: Total Sources | L15: =SUM(L9:L11) -> 29645153 | M15: =SUM(M9:M11) -> 1 | O15: Extension Fee | R15: 0.005 | S15: Mortgage Constant (%) | V15: =PMT(V13/12,V14*12,-1)*12 -> 0.079836299
O16: Exercise Extension? | Q16: DON’T EDIT | R16: =($Q$13=4)*1 -> 0 | S16: Origination | V16: =R13 -> 45291
F17: SCENARIO | J17: Exit Cap Rate | L17: =TerminalCapRateHotel -> 0.085 | O17: Extension Date | R17: =EOMONTH(R13,-12)*R16 -> 0 | S17: Maturity | T17: DON’T EDIT | U17: =DATEDIF(R13,V17,"y") -> 3 | V17: =ExitDate -> 46387
F18: Closing | H18: =Inputs!C11-1 -> 44196 | J18: Sales Costs | L18: =SellingCost -> 0.03 | O18: PREFERRED EQUITY | S18: Prepayment Fee | V18: 0.01
F19: Opening | H19: =EOMONTH(Construction!AC7,1) -> 44957 | J19: Gross Sales Proceeds | L19: =SUM(I52:CO52) -> 47973474 | O19: Preferred Equity | R19: 5000000 | S19: Prepay Loan? | U19: DON’T EDIT | V19: =IF(U17<=2, 1, 0) -> 0
F20: Sale Date | H20: =DATE(YEAR(H18) + HoldingPeriod + 1, MONTH(H18), DAY(H18)) -> 46387 | J20: Price per Key | L20: =L19/NumberRooms -> 191893.9 | O20: Preferred Equity Return | R20: 0.09
F22: Funding | H22: Position | I22: Weight
F23: =J11 -> Common Equity | H23: 1 | I23: 1
F24: =J10 -> Preferred Equity | H24: 2 | I24: 1
F25: =J9 -> Construction Loan | H25: 3 | I25: 1
H27: Year | I27: =YEAR(I28) -> 2020 | J27: =YEAR(J28) -> 2021 | K27: =YEAR(K28) -> 2021 | L27: =YEAR(L28) -> 2021 | M27: =YEAR(M28) -> 2021 | N27: =YEAR(N28) -> 2021 | O27: =YEAR(O28) -> 2021 | P27: =YEAR(P28) -> 2021 | ... CO27: =YEAR(CO28) -> 2027 | CP27: x
H28: Date | I28: =H18 -> 44196 | J28: =EOMONTH(I28,1) -> 44227 | K28: =EOMONTH(J28,1) -> 44255 | L28: =EOMONTH(K28,1) -> 44286 | M28: =EOMONTH(L28,1) -> 44316 | N28: =EOMONTH(M28,1) -> 44347 | O28: =EOMONTH(N28,1) -> 44377 | P28: =EOMONTH(O28,1) -> 44408 | Q28: =EOMONTH(P28,1) -> 44439 | ... CO28: =EOMONTH(CN28,1) -> 46752 | CP28: x
B29: Sum | C29: Comments | D29: Sign | H29: Days | I29: 31 | J29: =J28-I28 -> 31 | K29: =K28-J28 -> 28 | L29: =L28-K28 -> 31 | M29: =M28-L28 -> 30 | N29: =N28-M28 -> 31 | O29: =O28-N28 -> 30 | P29: =P28-O28 -> 31 | Q29: =Q28-P28 -> 31 | ... CO29: =CO28-CN28 -> 31 | CP29: x
F31: Cash Flows to Equity
C32: HINT: Index, Match, AND IFERROR functions will be helpful here.
C33: Make sure to divide by 12 for monthly! | D33: + | F33: Net Operating Income Hotel | I33: =IFERROR(INDEX(NOI!$C$76:$H$76,MATCH(I27,NOI!$C$8:$H$8,0))/12,0) -> 0 | J33: =IFERROR(INDEX(NOI!$C$76:$H$76,MATCH(J27,NOI!$C$8:$H$8,0))/12,0) -> 246463.73 | K33: =IFERROR(INDEX(NOI!$C$76:$H$76,MATCH(K27,NOI!$C$8:$H$8,0))/12,0) -> 246463.73 | L33: =IFERROR(INDEX(NOI!$C$76:$H$76,MATCH(L27,NOI!$C$8:$H$8,0))/12,0) -> 246463.73 | M33: =IFERROR(INDEX(NOI!$C$76:$H$76,MATCH(M27,NOI!$C$8:$H$8,0))/12,0) -> 246463.73 | N33: =IFERROR(INDEX(NOI!$C$76:$H$76,MATCH(N27,NOI!$C$8:$H$8,0))/12,0) -> 246463.73 | O33: =IFERROR(INDEX(NOI!$C$76:$H$76,MATCH(O27,NOI!$C$8:$H$8,0))/12,0) -> 246463.73 | P33: =IFERROR(INDEX(NOI!$C$76:$H$76,MATCH(P27,NOI!$C$8:$H$8,0))/12,0) -> 246463.73 | ... CO33: =IFERROR(INDEX(NOI!$C$76:$H$76,MATCH(CO27,NOI!$C$8:$H$8,0))/12,0) -> 0 | CP33: x
D35: + | F35: Selected Net Operating Income | I35: =(Today>=OpeningDate)*(Today<=ExitDate)*I33 -> 0 | J35: =(Today>=OpeningDate)*(Today<=ExitDate)*J33 -> 0 | K35: =(Today>=OpeningDate)*(Today<=ExitDate)*K33 -> 0 | L35: =(Today>=OpeningDate)*(Today<=ExitDate)*L33 -> 0 | M35: =(Today>=OpeningDate)*(Today<=ExitDate)*M33 -> 0 | N35: =(Today>=OpeningDate)*(Today<=ExitDate)*N33 -> 0 | O35: =(Today>=OpeningDate)*(Today<=ExitDate)*O33 -> 0 | P35: =(Today>=OpeningDate)*(Today<=ExitDate)*P33 -> 0 | ... CO35: =(Today>=OpeningDate)*(Today<=ExitDate)*CO33 -> 0 | CP35: x
C36: HINT: TTM = Trailing 12 month (OFFSET Function will be helpful here) | D36: + | F36: TTM NOI | I36: =IF(Today<OpeningDate,0,SUM(OFFSET(I35,,0,1,-12))) -> 0 | J36: =IF(Today<OpeningDate,0,SUM(OFFSET(J35,,0,1,-12))) -> 0 | K36: =IF(Today<OpeningDate,0,SUM(OFFSET(K35,,0,1,-12))) -> 0 | L36: =IF(Today<OpeningDate,0,SUM(OFFSET(L35,,0,1,-12))) -> 0 | M36: =IF(Today<OpeningDate,0,SUM(OFFSET(M35,,0,1,-12))) -> 0 | N36: =IF(Today<OpeningDate,0,SUM(OFFSET(N35,,0,1,-12))) -> 0 | O36: =IF(Today<OpeningDate,0,SUM(OFFSET(O35,,0,1,-12))) -> 0 | P36: =IF(Today<OpeningDate,0,SUM(OFFSET(P35,,0,1,-12))) -> 0 | ... CO36: =IF(Today<OpeningDate,0,SUM(OFFSET(CO35,,0,1,-12))) -> 0 | CP36: x
B38: =SUM(I38:CO38) -> 15868156 | C38: HINT: There should be no NOI after sale date (cell G20) | D38: + | F38: Net Operating Income | I38: =I35 -> 0 | J38: =J35 -> 0 | K38: =K35 -> 0 | L38: =L35 -> 0 | M38: =M35 -> 0 | N38: =N35 -> 0 | O38: =O35 -> 0 | P38: =P35 -> 0 | ... CO38: =CO35 -> 0 | CP38: x
B39: =SUM(I39:CO39) -> -28520153 | C39: HINT: Link to "Construction Budget" tab | D39: – | F39: Unlevered Development Costs | I39: =-Construction!E32 -> -8050223.9 | J39: =-Construction!F32 -> -311434.77 | K39: =-Construction!G32 -> -311434.77 | L39: =-Construction!H32 -> -334774.57 | M39: =-Construction!I32 -> -317269.72 | N39: =-Construction!J32 -> -268256.14 | O39: =-Construction!K32 -> -455644.58 | P39: =-Construction!L32 -> -697211.51 | ... CO39: =-Construction!CK32 -> 0 | CP39: x
B40: =SUM(I40:CO40) -> -125000 | C40: HINT: These should be paid at closing (cell G18) | D40: – | F40: Loan Fees | I40: =-ConstLoanOFees*(Today=ClosingDate) -> -125000 | J40: =-ConstLoanOFees*(Today=ClosingDate) -> 0 | K40: =-ConstLoanOFees*(Today=ClosingDate) -> 0 | L40: =-ConstLoanOFees*(Today=ClosingDate) -> 0 | M40: =-ConstLoanOFees*(Today=ClosingDate) -> 0 | N40: =-ConstLoanOFees*(Today=ClosingDate) -> 0 | O40: =-ConstLoanOFees*(Today=ClosingDate) -> 0 | P40: =-ConstLoanOFees*(Today=ClosingDate) -> 0 | ... CO40: =-ConstLoanOFees*(Today=ClosingDate) -> 0 | CP40: x
B41: =SUM(I41:CO41) -> -197955.79 | D41: – | F41: Construction Period Interest Draws | I41: =-I97 -> 0 | J41: =-J97 -> 0 | K41: =-K97 -> 0 | L41: =-L97 -> 0 | M41: =-M97 -> 0 | N41: =-N97 -> 0 | O41: =-O97 -> 0 | P41: =-P97 -> 0 | ... CO41: =-CO97 -> 0 | CP41: x
B42: =SUM(I42:CO42) -> 5000000 | D42: + | F42: Preferred Equity Funding | I42: =I82 -> 0 | J42: =J82 -> 0 | K42: =K82 -> 0 | L42: =L82 -> 0 | M42: =M82 -> 0 | N42: =N82 -> 0 | O42: =O82 -> 0 | P42: =P82 -> 0 | ... CO42: =CO82 -> 0 | CP42: x
B43: =SUM(I43:CO43) -> 11697956 | D43: + | F43: Construction Loan Funding | I43: =I88 -> 0 | J43: =J88 -> 0 | K43: =K88 -> 0 | L43: =L88 -> 0 | M43: =M88 -> 0 | N43: =N88 -> 0 | O43: =O88 -> 0 | P43: =P88 -> 0 | ... CO43: =CO88 -> 0 | CP43: x
B44: =SUM(I44:CO44) -> -564113.48 | C44: HINT: Interest expense less $ funded by construction interest draws | D44: – | F44: Construction Loan Interest | I44: =-I96+I97 -> 0 | J44: =-J96+J97 -> 0 | K44: =-K96+K97 -> 0 | L44: =-L96+L97 -> 0 | M44: =-M96+M97 -> 0 | N44: =-N96+N97 -> 0 | O44: =-O96+O97 -> 0 | P44: =-P96+P97 -> 0 | ... CO44: =-CO96+CO97 -> 0 | CP44: x
B45: =SUM(I45:CO45) -> 0 | C45: HINT: Only payable if you refinance in Year 4 | D45: – | F45: Construction Loan Extension Payment | I45: =-ConstLoanExtensionDummy*(ConstLoanExtensionFee*I87)*(Today=ConstLoanExtensionDate) -> 0 | J45: =-ConstLoanExtensionDummy*(ConstLoanExtensionFee*J87)*(Today=ConstLoanExtensionDate) -> 0 | K45: =-ConstLoanExtensionDummy*(ConstLoanExtensionFee*K87)*(Today=ConstLoanExtensionDate) -> 0 | L45: =-ConstLoanExtensionDummy*(ConstLoanExtensionFee*L87)*(Today=ConstLoanExtensionDate) -> 0 | M45: =-ConstLoanExtensionDummy*(ConstLoanExtensionFee*M87)*(Today=ConstLoanExtensionDate) -> 0 | N45: =-ConstLoanExtensionDummy*(ConstLoanExtensionFee*N87)*(Today=ConstLoanExtensionDate) -> 0 | O45: =-ConstLoanExtensionDummy*(ConstLoanExtensionFee*O87)*(Today=ConstLoanExtensionDate) -> 0 | P45: =-ConstLoanExtensionDummy*(ConstLoanExtensionFee*P87)*(Today=ConstLoanExtensionDate) -> 0 | ... CO45: =-ConstLoanExtensionDummy*(ConstLoanExtensionFee*CO87)*(Today=ConstLoanExtensionDate) -> 0 | CP45: x
B46: =SUM(I46:CO46) -> -11697956 | D46: – | F46: Construction Loan Repayment | I46: =I89 -> 0 | J46: =J89 -> 0 | K46: =K89 -> 0 | L46: =L89 -> 0 | M46: =M89 -> 0 | N46: =N89 -> 0 | O46: =O89 -> 0 | P46: =P89 -> 0 | ... CO46: =CO89 -> 0 | CP46: x
B47: =SUM(I47:CO47) -> 35005242 | D47: + | F47: Permanent Loan Proceeds | I47: =I101 -> 0 | J47: =J101 -> 0 | K47: =K101 -> 0 | L47: =L101 -> 0 | M47: =M101 -> 0 | N47: =N101 -> 0 | O47: =O101 -> 0 | P47: =P101 -> 0 | ... CO47: =CO101 -> 0 | CP47: x
